<?xml version="1.0" ?>
<!-- =================================================================================== -->
<!-- |    This document was autogenerated by xacro from pipebot.xacro                  | -->
<!-- |    EDITING THIS FILE BY HAND IS NOT RECOMMENDED                                 | -->
<!-- =================================================================================== -->
<robot name="pipebot">
  <material name="silver">
    <color rgba="0.700 0.700 0.700 1.000"/>
  </material>
  <transmission name="FR_hip_joint_tran">
    <type>transmission_interface/SimpleTransmission</type>
    <joint name="FR_hip_joint">
      <hardwareInterface>hardware_interface/EffortJointInterface</hardwareInterface>
    </joint>
    <actuator name="FR_hip_joint_actr">
      <hardwareInterface>hardware_interface/EffortJointInterface</hardwareInterface>
      <mechanicalReduction>1</mechanicalReduction>
    </actuator>
  </transmission>
  <transmission name="FL_hip_joint_tran">
    <type>transmission_interface/SimpleTransmission</type>
    <joint name="FL_hip_joint">
      <hardwareInterface>hardware_interface/EffortJointInterface</hardwareInterface>
    </joint>
    <actuator name="FL_hip_joint_actr">
      <hardwareInterface>hardware_interface/EffortJointInterface</hardwareInterface>
      <mechanicalReduction>1</mechanicalReduction>
    </actuator>
  </transmission>
  <transmission name="BR_hip_joint_tran">
    <type>transmission_interface/SimpleTransmission</type>
    <joint name="BR_hip_joint">
      <hardwareInterface>hardware_interface/EffortJointInterface</hardwareInterface>
    </joint>
    <actuator name="BR_hip_joint_actr">
      <hardwareInterface>hardware_interface/EffortJointInterface</hardwareInterface>
      <mechanicalReduction>1</mechanicalReduction>
    </actuator>
  </transmission>
  <transmission name="BL_hip_joint_tran">
    <type>transmission_interface/SimpleTransmission</type>
    <joint name="BL_hip_joint">
      <hardwareInterface>hardware_interface/EffortJointInterface</hardwareInterface>
    </joint>
    <actuator name="BL_hip_joint_actr">
      <hardwareInterface>hardware_interface/EffortJointInterface</hardwareInterface>
      <mechanicalReduction>1</mechanicalReduction>
    </actuator>
  </transmission>
  <transmission name="FR_thigh_joint_tran">
    <type>transmission_interface/SimpleTransmission</type>
    <joint name="FR_thigh_joint">
      <hardwareInterface>hardware_interface/EffortJointInterface</hardwareInterface>
    </joint>
    <actuator name="FR_thigh_joint_actr">
      <hardwareInterface>hardware_interface/EffortJointInterface</hardwareInterface>
      <mechanicalReduction>1</mechanicalReduction>
    </actuator>
  </transmission>
  <transmission name="FL_thigh_joint_tran">
    <type>transmission_interface/SimpleTransmission</type>
    <joint name="FL_thigh_joint">
      <hardwareInterface>hardware_interface/EffortJointInterface</hardwareInterface>
    </joint>
    <actuator name="FL_thigh_joint_actr">
      <hardwareInterface>hardware_interface/EffortJointInterface</hardwareInterface>
      <mechanicalReduction>1</mechanicalReduction>
    </actuator>
  </transmission>
  <transmission name="BR_thigh_joint_tran">
    <type>transmission_interface/SimpleTransmission</type>
    <joint name="BR_thigh_joint">
      <hardwareInterface>hardware_interface/EffortJointInterface</hardwareInterface>
    </joint>
    <actuator name="BR_thigh_joint_actr">
      <hardwareInterface>hardware_interface/EffortJointInterface</hardwareInterface>
      <mechanicalReduction>1</mechanicalReduction>
    </actuator>
  </transmission>
  <transmission name="BL_thigh_joint_tran">
    <type>transmission_interface/SimpleTransmission</type>
    <joint name="BL_thigh_joint">
      <hardwareInterface>hardware_interface/EffortJointInterface</hardwareInterface>
    </joint>
    <actuator name="BL_thigh_joint_actr">
      <hardwareInterface>hardware_interface/EffortJointInterface</hardwareInterface>
      <mechanicalReduction>1</mechanicalReduction>
    </actuator>
  </transmission>
  <transmission name="FR_calf_joint_tran">
    <type>transmission_interface/SimpleTransmission</type>
    <joint name="FR_calf_joint">
      <hardwareInterface>hardware_interface/EffortJointInterface</hardwareInterface>
    </joint>
    <actuator name="FR_calf_joint_actr">
      <hardwareInterface>hardware_interface/EffortJointInterface</hardwareInterface>
      <mechanicalReduction>1</mechanicalReduction>
    </actuator>
  </transmission>
  <transmission name="FL_calf_joint_tran">
    <type>transmission_interface/SimpleTransmission</type>
    <joint name="FL_calf_joint">
      <hardwareInterface>hardware_interface/EffortJointInterface</hardwareInterface>
    </joint>
    <actuator name="FL_calf_joint_actr">
      <hardwareInterface>hardware_interface/EffortJointInterface</hardwareInterface>
      <mechanicalReduction>1</mechanicalReduction>
    </actuator>
  </transmission>
  <transmission name="BR_calf_joint_tran">
    <type>transmission_interface/SimpleTransmission</type>
    <joint name="BR_calf_joint">
      <hardwareInterface>hardware_interface/EffortJointInterface</hardwareInterface>
    </joint>
    <actuator name="BR_calf_joint_actr">
      <hardwareInterface>hardware_interface/EffortJointInterface</hardwareInterface>
      <mechanicalReduction>1</mechanicalReduction>
    </actuator>
  </transmission>
  <transmission name="BL_calf_joint_tran">
    <type>transmission_interface/SimpleTransmission</type>
    <joint name="BL_calf_joint">
      <hardwareInterface>hardware_interface/EffortJointInterface</hardwareInterface>
    </joint>
    <actuator name="BL_calf_joint_actr">
      <hardwareInterface>hardware_interface/EffortJointInterface</hardwareInterface>
      <mechanicalReduction>1</mechanicalReduction>
    </actuator>
  </transmission>  
  <gazebo>
    <plugin filename="libgazebo_ros_control.so" name="control"/>
  </gazebo>
  <gazebo reference="base_link">
    <material>Gazebo/DarkGrey</material>
    <mu1>0.2</mu1>
    <mu2>0.2</mu2>
    <gravity>true</gravity>
  </gazebo>
  <gazebo reference="FR_hip_1">
    <material>Gazebo/Grey</material>
    <mu1>0.2</mu1>
    <mu2>0.2</mu2>
  </gazebo>
  <gazebo reference="FL_hip_1">
    <material>Gazebo/Grey</material>
    <mu1>0.2</mu1>
    <mu2>0.2</mu2>
  </gazebo>
  <gazebo reference="BR_hip_1">
    <material>Gazebo/Grey</material>
    <mu1>0.2</mu1>
    <mu2>0.2</mu2>
  </gazebo>
  <gazebo reference="BL_hip_2">
    <material>Gazebo/Grey</material>
    <mu1>0.2</mu1>
    <mu2>0.2</mu2>
  </gazebo>
  <gazebo reference="FR_thigh_2">
    <material>Gazebo/DarkGrey</material>
    <mu1>0.2</mu1>
    <mu2>0.2</mu2>
  </gazebo>
  <gazebo reference="FL_thigh_1">
    <material>Gazebo/DarkGrey</material>
    <mu1>0.2</mu1>
    <mu2>0.2</mu2>
  </gazebo>
  <gazebo reference="BR_thigh_1">
    <material>Gazebo/DarkGrey</material>
    <mu1>0.2</mu1>
    <mu2>0.2</mu2>
  </gazebo>
  <gazebo reference="BL_thigh_1">
    <material>Gazebo/DarkGrey</material>
    <mu1>0.2</mu1>
    <mu2>0.2</mu2>
  </gazebo>
  <gazebo reference="FR_calf_2">
    <material>Gazebo/DarkGrey</material>
    <mu1>0.2</mu1>
    <mu2>0.2</mu2>
  </gazebo>
  <gazebo reference="FL_calf_1">
    <material>Gazebo/DarkGrey</material>
    <mu1>0.2</mu1>
    <mu2>0.2</mu2>
  </gazebo>
  <gazebo reference="BR_calf_1">
    <material>Gazebo/DarkGrey</material>
    <mu1>0.2</mu1>
    <mu2>0.2</mu2>
  </gazebo>
  <gazebo reference="BL_calf_1">
    <material>Gazebo/DarkGrey</material>
    <mu1>0.2</mu1>
    <mu2>0.2</mu2>
  </gazebo>
  <gazebo reference="FL_foot_1">
    <material>Gazebo/Black</material>
      <mu1>10.0</mu1>
      <mu2>10.0</mu2>
      <kp>1000000.0</kp>
      <kd>1000.0</kd>
      <minDepth>0.01</minDepth>
      <maxVel>1.0</maxVel>
  </gazebo>
  <gazebo reference="FR_foot_1">
    <material>Gazebo/Black</material>
      <mu1>10.0</mu1>
      <mu2>10.0</mu2>
      <kp>1000000.0</kp>
      <kd>1000.0</kd>
      <minDepth>0.01</minDepth>
      <maxVel>1.0</maxVel>
  </gazebo>
  <gazebo reference="BR_foot_4">
    <material>Gazebo/Black</material>
      <mu1>10.0</mu1>
      <mu2>10.0</mu2>
      <kp>1000000.0</kp>
      <kd>1000.0</kd>
      <minDepth>0.01</minDepth>
      <maxVel>1.0</maxVel>
  </gazebo>
  <gazebo reference="BL_foot_1">    
    <material>Gazebo/Black</material>
      <mu1>10.0</mu1>
      <mu2>10.0</mu2>
      <kp>1000000.0</kp>
      <kd>1000.0</kd>
      <minDepth>0.01</minDepth>
      <maxVel>1.0</maxVel>
  </gazebo>
  <link name="base_link">
    <inertial>
      <origin rpy="0 0 0" xyz="0.0033827602101410043 -0.00027510616293287325 0.07066379377055013"/>
      <mass value="14.029718208807811"/>      
      <inertia ixx="0.085792" ixy="-4e-06" ixz="-0.005638" iyy="0.321558" iyz="-0.0" izz="0.365464"/>
    </inertial>
    <visual>
      <origin rpy="0 0 0" xyz="0 0 0"/>
      <geometry>
        <mesh filename="package://pipebot_config/meshes/base_link.stl" scale="0.001 0.001 0.001"/>
      </geometry>
      <material name="silver"/>
    </visual>
    <collision>
      <origin rpy="0 0 0" xyz="0 0 0"/>
      <geometry>
        <mesh filename="package://pipebot_config/meshes/base_link.stl" scale="0.001 0.001 0.001"/>
      </geometry>
    </collision>
  </link>
  <link name="FR_hip_1">
    <inertial>
      <origin rpy="0 0 0" xyz="0.05534495479566107 -0.008820712971960562 -3.2335245592207684e-15"/>
      <mass value="0.5405625696384098"/>
      <inertia ixx="0.000528" ixy="-2e-06" ixz="-0.0" iyy="0.000646" iyz="-0.0" izz="0.000551"/>
    </inertial>
    <visual>
      <origin rpy="0 0 0" xyz="-0.0897 0.110275 -0.0675"/>
      <geometry>
        <mesh filename="package://pipebot_config/meshes/FR_hip_1.stl" scale="0.001 0.001 0.001"/>
      </geometry>
      <material name="silver"/>
    </visual>
    <collision>
      <origin rpy="0 0 0" xyz="-0.0897 0.110275 -0.0675"/>
      <geometry>
        <mesh filename="package://pipebot_config/meshes/FR_hip_1.stl" scale="0.001 0.001 0.001"/>
      </geometry>
    </collision>
  </link>
  <link name="FL_hip_1">
    <inertial>
      <origin rpy="0 0 0" xyz="0.05534495479566112 0.008821436558665019 3.066991105526995e-15"/>
      <mass value="0.5405625696384098"/>
      <inertia ixx="0.000528" ixy="2e-06" ixz="0.0" iyy="0.000646" iyz="-0.0" izz="0.000551"/>
    </inertial>
    <visual>
      <origin rpy="0 0 0" xyz="-0.0897 -0.109725 -0.0675"/>
      <geometry>
        <mesh filename="package://pipebot_config/meshes/FL_hip_1.stl" scale="0.001 0.001 0.001"/>
      </geometry>
      <material name="silver"/>
    </visual>
    <collision>
      <origin rpy="0 0 0" xyz="-0.0897 -0.109725 -0.0675"/>
      <geometry>
        <mesh filename="package://pipebot_config/meshes/FL_hip_1.stl" scale="0.001 0.001 0.001"/>
      </geometry>
    </collision>
  </link>
  <link name="BR_hip_1">
    <inertial>
      <origin rpy="0 0 0" xyz="-0.05534530530947 -0.00882071297196084 2.9837243786801082e-15"/>
      <mass value="0.5405625696384098"/>
      <inertia ixx="0.000528" ixy="2e-06" ixz="-0.0" iyy="0.000646" iyz="0.0" izz="0.000551"/>
    </inertial>
    <visual>
      <origin rpy="0 0 0" xyz="0.0903 0.110275 -0.0675"/>
      <geometry>
        <mesh filename="package://pipebot_config/meshes/BR_hip_1.stl" scale="0.001 0.001 0.001"/>
      </geometry>
      <material name="silver"/>
    </visual>
    <collision>
      <origin rpy="0 0 0" xyz="0.0903 0.110275 -0.0675"/>
      <geometry>
        <mesh filename="package://pipebot_config/meshes/BR_hip_1.stl" scale="0.001 0.001 0.001"/>
      </geometry>
    </collision>
  </link>
  <link name="BL_hip_2">
    <inertial>
      <origin rpy="0 0 0" xyz="-0.05534530530946975 0.008821436558665116 -3.3029134982598407e-15"/>
      <mass value="0.5405625696384098"/>
      <inertia ixx="0.000528" ixy="-2e-06" ixz="0.0" iyy="0.000646" iyz="0.0" izz="0.000551"/>
    </inertial>
    <visual>
      <origin rpy="0 0 0" xyz="0.0903 -0.109725 -0.0675"/>
      <geometry>
        <mesh filename="package://pipebot_config/meshes/BL_hip_2.stl" scale="0.001 0.001 0.001"/>
      </geometry>
      <material name="silver"/>
    </visual>
    <collision>
      <origin rpy="0 0 0" xyz="0.0903 -0.109725 -0.0675"/>
      <geometry>
        <mesh filename="package://pipebot_config/meshes/BL_hip_2.stl" scale="0.001 0.001 0.001"/>
      </geometry>
    </collision>
  </link>
  <link name="FR_thigh_2">
    <inertial>
      <origin rpy="0 0 0" xyz="-1.752569043500518e-07 0.008553923180792372 -0.1460839641861526"/>
      <mass value="0.6712775800969663"/>
      <inertia ixx="0.004329" ixy="-0.0" ixz="-0.0" iyy="0.004392" iyz="0.000581" izz="0.000652"/>
    </inertial>
    <visual>
      <origin rpy="0 0 0" xyz="-0.1447 0.160275 -0.0675"/>
      <geometry>
        <mesh filename="package://pipebot_config/meshes/FR_thigh_2.stl" scale="0.001 0.001 0.001"/>
      </geometry>
      <material name="silver"/>
    </visual>
    <collision>
      <origin rpy="0 0 0" xyz="-0.1447 0.160275 -0.0675"/>
      <geometry>
        <mesh filename="package://pipebot_config/meshes/FR_thigh_2.stl" scale="0.001 0.001 0.001"/>
      </geometry>
    </collision>
  </link>
  <link name="FL_thigh_1">
    <inertial>
      <origin rpy="0 0 0" xyz="-1.7525690446107411e-07 -0.008553199594087929 -0.1460839641861526"/>
      <mass value="0.6712775800969663"/>
      <inertia ixx="0.004329" ixy="-0.0" ixz="0.0" iyy="0.004392" iyz="-0.000581" izz="0.000652"/>
    </inertial>
    <visual>
      <origin rpy="0 0 0" xyz="-0.1447 -0.159725 -0.0675"/>
      <geometry>
        <mesh filename="package://pipebot_config/meshes/FL_thigh_1.stl" scale="0.001 0.001 0.001"/>
      </geometry>
      <material name="silver"/>
    </visual>
    <collision>
      <origin rpy="0 0 0" xyz="-0.1447 -0.159725 -0.0675"/>
      <geometry>
        <mesh filename="package://pipebot_config/meshes/FL_thigh_1.stl" scale="0.001 0.001 0.001"/>
      </geometry>
    </collision>
  </link>
  <link name="BR_thigh_1">
    <inertial>
      <origin rpy="0 0 0" xyz="-1.7525690446107411e-07 0.008553923180792067 -0.14608396418615266"/>
      <mass value="0.6712775800969663"/>
      <inertia ixx="0.004329" ixy="0.0" ixz="0.0" iyy="0.004392" iyz="0.000581" izz="0.000652"/>
    </inertial>
    <visual>
      <origin rpy="0 0 0" xyz="0.1453 0.160275 -0.0675"/>
      <geometry>
        <mesh filename="package://pipebot_config/meshes/BR_thigh_1.stl" scale="0.001 0.001 0.001"/>
      </geometry>
      <material name="silver"/>
    </visual>
    <collision>
      <origin rpy="0 0 0" xyz="0.1453 0.160275 -0.0675"/>
      <geometry>
        <mesh filename="package://pipebot_config/meshes/BR_thigh_1.stl" scale="0.001 0.001 0.001"/>
      </geometry>
    </collision>
  </link>
  <link name="BL_thigh_1">
    <inertial>
      <origin rpy="0 0 0" xyz="-1.7525690432229624e-07 -0.008553199594087763 -0.14608396418615266"/>
      <mass value="0.6712775800969663"/>
      <inertia ixx="0.004329" ixy="0.0" ixz="-0.0" iyy="0.004392" iyz="-0.000581" izz="0.000652"/>
    </inertial>
    <visual>
      <origin rpy="0 0 0" xyz="0.1453 -0.159725 -0.0675"/>
      <geometry>
        <mesh filename="package://pipebot_config/meshes/BL_thigh_1.stl" scale="0.001 0.001 0.001"/>
      </geometry>
      <material name="silver"/>
    </visual>
    <collision>
      <origin rpy="0 0 0" xyz="0.1453 -0.159725 -0.0675"/>
      <geometry>
        <mesh filename="package://pipebot_config/meshes/BL_thigh_1.stl" scale="0.001 0.001 0.001"/>
      </geometry>
    </collision>
  </link>
  <link name="FR_calf_2">
    <inertial>
      <origin rpy="0 0 0" xyz="-6.545205563368572e-07 -0.026638451213781028 -0.06322775699684074"/>
      <mass value="0.44827046160119605"/>
      <inertia ixx="0.002095" ixy="0.0" ixz="0.0" iyy="0.002115" iyz="-7.1e-05" izz="0.000179"/>
    </inertial>
    <visual>
      <origin rpy="0 0 0" xyz="-0.1447 0.180275 0.1325"/>
      <geometry>
        <mesh filename="package://pipebot_config/meshes/FR_calf_2.stl" scale="0.001 0.001 0.001"/>
      </geometry>
      <material name="silver"/>
    </visual>
    <collision>
      <origin rpy="0 0 0" xyz="-0.1447 0.180275 0.1325"/>
      <geometry>
        <mesh filename="package://pipebot_config/meshes/FR_calf_2.stl" scale="0.001 0.001 0.001"/>
      </geometry>
    </collision>
  </link>
  <link name="FL_calf_1">
    <inertial>
      <origin rpy="0 0 0" xyz="3.0400674758124246e-07 0.02663917480048489 -0.06322775699684105"/>
      <mass value="0.44827046160119605"/>
      <inertia ixx="0.002095" ixy="0.0" ixz="-0.0" iyy="0.002115" iyz="7.1e-05" izz="0.000179"/>
    </inertial>
    <visual>
      <origin rpy="0 0 0" xyz="-0.1447 -0.179725 0.1325"/>
      <geometry>
        <mesh filename="package://pipebot_config/meshes/FL_calf_1.stl" scale="0.001 0.001 0.001"/>
      </geometry>
      <material name="silver"/>
    </visual>
    <collision>
      <origin rpy="0 0 0" xyz="-0.1447 -0.179725 0.1325"/>
      <geometry>
        <mesh filename="package://pipebot_config/meshes/FL_calf_1.stl" scale="0.001 0.001 0.001"/>
      </geometry>
    </collision>
  </link>
  <link name="BR_calf_1">
    <inertial>
      <origin rpy="0 0 0" xyz="-6.545205564478795e-07 -0.026638451213780612 -0.06322775699684094"/>
      <mass value="0.44827046160119605"/>
      <inertia ixx="0.002095" ixy="0.0" ixz="0.0" iyy="0.002115" iyz="-7.1e-05" izz="0.000179"/>
    </inertial>
    <visual>
      <origin rpy="0 0 0" xyz="0.1453 0.180275 0.1325"/>
      <geometry>
        <mesh filename="package://pipebot_config/meshes/BR_calf_1.stl" scale="0.001 0.001 0.001"/>
      </geometry>
      <material name="silver"/>
    </visual>
    <collision>
      <origin rpy="0 0 0" xyz="0.1453 0.180275 0.1325"/>
      <geometry>
        <mesh filename="package://pipebot_config/meshes/BR_calf_1.stl" scale="0.001 0.001 0.001"/>
      </geometry>
    </collision>
  </link>
  <link name="BL_calf_1">
    <inertial>
      <origin rpy="0 0 0" xyz="3.0400674780328707e-07 0.026639174800485 -0.06322775699683994"/>
      <mass value="0.44827046160119605"/>
      <inertia ixx="0.002095" ixy="0.0" ixz="-0.0" iyy="0.002115" iyz="7.1e-05" izz="0.000179"/>
    </inertial>
    <visual>
      <origin rpy="0 0 0" xyz="0.1453 -0.179725 0.1325"/>
      <geometry>
        <mesh filename="package://pipebot_config/meshes/BL_calf_1.stl" scale="0.001 0.001 0.001"/>
      </geometry>
      <material name="silver"/>
    </visual>
    <collision>
      <origin rpy="0 0 0" xyz="0.1453 -0.179725 0.1325"/>
      <geometry>
        <mesh filename="package://pipebot_config/meshes/BL_calf_1.stl" scale="0.001 0.001 0.001"/>
      </geometry>
    </collision>
  </link>

  <link name="FL_foot_1">
    <inertial>
      <origin rpy="0 0 0" xyz="-1.7525690432229624e-07 3.6179335244357347e-07 -0.0018890805472966399"/>
      <mass value="0.05646802367385563"/>
      <inertia ixx="1.4e-05" ixy="0.0" ixz="0.0" iyy="1.4e-05" iyz="0.0" izz="1.6e-05"/>
    </inertial>
    <visual>
      <origin rpy="0 0 0" xyz="-0.1447 -0.209725 0.3825"/>
      <geometry>
        <mesh filename="package://pipebot_config/meshes/FL_foot_1.stl" scale="0.001 0.001 0.001"/>
      </geometry>
      <material name="silver"/>
    </visual>
    <collision>
      <origin rpy="0 0 0" xyz="-0.1447 -0.209725 0.3825"/>
      <geometry>
        <mesh filename="package://pipebot_config/meshes/FL_foot_1.stl" scale="0.001 0.001 0.001"/>
      </geometry>
    </collision>
  </link>
  <link name="FR_foot_1">
    <inertial>
      <origin rpy="0 0 0" xyz="-1.7525690426678509e-07 3.617933521660177e-07 -0.0018890805472965844"/>
      <mass value="0.05646802367385563"/>
      <inertia ixx="1.4e-05" ixy="-0.0" ixz="0.0" iyy="1.4e-05" iyz="0.0" izz="1.6e-05"/>
    </inertial>
    <visual>
      <origin rpy="0 0 0" xyz="-0.1447 0.210275 0.3825"/>
      <geometry>
        <mesh filename="package://pipebot_config/meshes/FR_foot_1.stl" scale="0.001 0.001 0.001"/>
      </geometry>
      <material name="silver"/>
    </visual>
    <collision>
      <origin rpy="0 0 0" xyz="-0.1447 0.210275 0.3825"/>
      <geometry>
        <mesh filename="package://pipebot_config/meshes/FR_foot_1.stl" scale="0.001 0.001 0.001"/>
      </geometry>
    </collision>
  </link>
  <link name="BR_foot_4">
    <inertial>
      <origin rpy="0 0 0" xyz="-1.752569043500518e-07 3.6179335222152886e-07 -0.0018890805472984162"/>
      <mass value="0.05646802367385563"/>
      <inertia ixx="1.4e-05" ixy="-0.0" ixz="0.0" iyy="1.4e-05" iyz="-0.0" izz="1.6e-05"/>
    </inertial>
    <visual>
      <origin rpy="0 0 0" xyz="0.1453 0.210275 0.3825"/>
      <geometry>
        <mesh filename="package://pipebot_config/meshes/BR_foot_4.stl" scale="0.001 0.001 0.001"/>
      </geometry>
      <material name="silver"/>
    </visual>
    <collision>
      <origin rpy="0 0 0" xyz="0.1453 0.210275 0.3825"/>
      <geometry>
        <mesh filename="package://pipebot_config/meshes/BR_foot_4.stl" scale="0.001 0.001 0.001"/>
      </geometry>
    </collision>
  </link>
  <link name="BL_foot_1">
    <inertial>
      <origin rpy="0 0 0" xyz="-1.7525690507169678e-07 3.617933526101069e-07 -0.0018890805472970285"/>
      <mass value="0.05646802367385563"/>
      <inertia ixx="1.4e-05" ixy="0.0" ixz="0.0" iyy="1.4e-05" iyz="0.0" izz="1.6e-05"/>
    </inertial>
    <visual>
      <origin rpy="0 0 0" xyz="0.1453 -0.209725 0.3825"/>
      <geometry>
        <mesh filename="package://pipebot_config/meshes/BL_foot_1.stl" scale="0.001 0.001 0.001"/>
      </geometry>
      <material name="silver"/>
    </visual>
    <collision>
      <origin rpy="0 0 0" xyz="0.1453 -0.209725 0.3825"/>
      <geometry>
        <mesh filename="package://pipebot_config/meshes/BL_foot_1.stl" scale="0.001 0.001 0.001"/>
      </geometry>
    </collision>
  </link>
  <joint name="FR_hip_joint" type="continuous">
    <origin rpy="0 0 0" xyz="0.0897 -0.110275 0.0675"/>
    <parent link="base_link"/>
    <child link="FR_hip_1"/>
    <axis xyz="1.0 -0.0 0.0"/>
    <limit lower="-3." upper="3.0" effort="40.0" velocity="15"/>
  </joint>
  <joint name="FL_hip_joint" type="continuous">
    <origin rpy="0 0 0" xyz="0.0897 0.109725 0.0675"/>
    <parent link="base_link"/>
    <child link="FL_hip_1"/>
    <axis xyz="1.0 -0.0 0.0"/>
    <limit lower="-3." upper="3.0" effort="40.0" velocity="15"/>
  </joint>
  <joint name="BR_hip_joint" type="continuous">
    <origin rpy="0 0 0" xyz="-0.0903 -0.110275 0.0675"/>
    <parent link="base_link"/>
    <child link="BR_hip_1"/>
    <axis xyz="1.0 0.0 -0.0"/>
    <limit lower="-3." upper="3.0" effort="40.0" velocity="15"/>
  </joint>
  <joint name="BL_hip_joint" type="continuous">
    <origin rpy="0 0 0" xyz="-0.0903 0.109725 0.0675"/>
    <parent link="base_link"/>
    <child link="BL_hip_2"/>
    <axis xyz="1.0 0.0 -0.0"/>
    <limit lower="-3." upper="3.0" effort="40.0" velocity="15"/>
  </joint>
  <joint name="FR_thigh_joint" type="continuous">
    <origin rpy="0 0 0" xyz="0.055 -0.05 0.0"/>
    <parent link="FR_hip_1"/>
    <child link="FR_thigh_2"/>
    <axis xyz="0.0 1.0 -0.0"/>
    <limit lower="-3." upper="3.0" effort="40.0" velocity="15"/>
  </joint>
  <joint name="FL_thigh_joint" type="continuous">
    <origin rpy="0 0 0" xyz="0.055 0.05 0.0"/>
    <parent link="FL_hip_1"/>
    <child link="FL_thigh_1"/>
    <axis xyz="-0.0 1.0 -0.0"/>
    <limit lower="-3." upper="3.0" effort="40.0" velocity="15"/>
  </joint>
  <joint name="BR_thigh_joint" type="continuous">
    <origin rpy="0 0 0" xyz="-0.055 -0.05 0.0"/>
    <parent link="BR_hip_1"/>
    <child link="BR_thigh_1"/>
    <axis xyz="0.0 1.0 0.0"/>
    <limit lower="-3." upper="3.0" effort="40.0" velocity="15"/>
  </joint>
  <joint name="BL_thigh_joint" type="continuous">
    <origin rpy="0 0 0" xyz="-0.055 0.05 0.0"/>
    <parent link="BL_hip_2"/>
    <child link="BL_thigh_1"/>
    <axis xyz="-0.0 1.0 0.0"/>
    <limit lower="-3." upper="3.0" effort="40.0" velocity="15"/>
  </joint>
  <joint name="FR_calf_joint" type="continuous">
    <origin rpy="0 0 0" xyz="0.0 -0.02 -0.2"/>
    <parent link="FR_thigh_2"/>
    <child link="FR_calf_2"/>
    <axis xyz="0.0 1.0 -0.0"/>
    <limit lower="-3." upper="3.0" effort="40.0" velocity="15"/>
  </joint>
  <joint name="FL_calf_joint" type="continuous">
    <origin rpy="0 0 0" xyz="0.0 0.02 -0.2"/>
    <parent link="FL_thigh_1"/>
    <child link="FL_calf_1"/>
    <axis xyz="-0.0 1.0 -0.0"/>
    <limit lower="-3." upper="3.0" effort="40.0" velocity="15"/>
  </joint>
  <joint name="BR_calf_joint" type="continuous">
    <origin rpy="0 0 0" xyz="0.0 -0.02 -0.2"/>
    <parent link="BR_thigh_1"/>
    <child link="BR_calf_1"/>
    <axis xyz="0.0 1.0 0.0"/>
    <limit lower="-3." upper="3.0" effort="40.0" velocity="15"/>
  </joint>
  <joint name="BL_calf_joint" type="continuous">
    <origin rpy="0 0 0" xyz="0.0 0.02 -0.2"/>
    <parent link="BL_thigh_1"/>
    <child link="BL_calf_1"/>
    <axis xyz="-0.0 1.0 0.0"/>
    <limit lower="-3." upper="3.0" effort="40.0" velocity="15"/>
  </joint>
    <joint name="FL_foot_fixed" type="fixed">
    <origin rpy="0 0 0" xyz="0.0 0.03 -0.25"/>
    <parent link="FL_calf_1"/>
    <child link="FL_foot_1"/>
  </joint>
  <joint name="FR_foot_fixed" type="fixed">
    <origin rpy="0 0 0" xyz="0.0 -0.03 -0.25"/>
    <parent link="FR_calf_2"/>
    <child link="FR_foot_1"/>
  </joint>
  <joint name="BR_foot_fixed" type="fixed">
    <origin rpy="0 0 0" xyz="0.0 -0.03 -0.25"/>
    <parent link="BR_calf_1"/>
    <child link="BR_foot_4"/>
  </joint>
  <joint name="BL_foot_fixed" type="fixed">
    <origin rpy="0 0 0" xyz="0.0 0.03 -0.25"/>
    <parent link="BL_calf_1"/>
    <child link="BL_foot_1"/>
  </joint>


</robot>

